Workbook

Sheet LEIA-ME
A1: Benchmark do Auditor BIM de Acessibilidade (NBR 9050:2020)
A3: O que é
A4: Teste de injeção controlada de erros: 30 variantes IFC geradas por script a partir do modelo-base BENCHMARK_00_3.ifc (100% conforme), cada uma com erros conhecidos e tabelados ANTES da execução (gabarito pré-registrado, commit acaa304).
A6: Ambiente das rodadas (computador do projeto, 03/10/2026)
A7: Windows · Python 3.12 · ifcopenshell 0.9.0 · LLM claude-sonnet-4-5, temperatura 0 · rodar_benchmark.py --llm anthropic
A8: v1 = primeira rodada completa (revelou o bug da altura da bacia). v2 = rodada após a correção — é a REFERÊNCIA da dissertação.
A10: Três camadas
A11: python = verificação determinística (geometria e propriedades do IFC).
A12: llm = veredito do modelo de linguagem sozinho.
A13: final = o que o relatório mostra: o Python sobrescreve o LLM nos itens que mede ('LLM traduz, Python julga'). O Python não mede o 7.7.1; ali vale o LLM.
A15: Definições (unidade = par variante × item; 30 × 12 = 360 pares)
A16: Positivo real: status esperado diferente de Conforme e de N/A.
... A40: Gerada por benchmark/montar_planilha.py a partir dos CSVs do repositório.

Sheet Resumo
A1: Benchmark do Auditor NBR 9050 — resultados (30 variantes × 12 itens = 360 pares)
A2: Todas as métricas abaixo são fórmulas sobre as abas 'Classificação v2' e 'Classificação v1'. v2 = rodada de referência (após a correção da altura da bacia).
A4: 1. Rodada v2 (referência) — métricas globais por camada
A5: Camada | B5: Critério | C5: n | D5: VP | E5: FP | F5: FN | G5: VN | H5: Acurácia | I5: Precisão | J5: Recall | K5: F1
A6: python | B6: estrito | C6: =D6+E6+F6+G6 -> 328 | D6: =COUNTIFS('Classificação v2'!$I$2:$I$361,"VP") -> 27 | E6: =COUNTIFS('Classificação v2'!$I$2:$I$361,"FP") -> 0 | F6: =COUNTIFS('Classificação v2'!$I$2:$I$361,"FN") -> 2 | G6: =COUNTIFS('Classificação v2'!$I$2:$I$361,"VN") -> 299 | H6: =IFERROR((D6+G6)/C6,"—") -> 0.99390244 | I6: =IFERROR(D6/(D6+E6),"—") -> 1 | J6: =IFERROR(D6/(D6+F6),"—") -> 0.93103448 | K6: =IFERROR(2*I6*J6/(I6+J6),"—") -> 0.96428571
A7: python | B7: amplo | C7: =D7+E7+F7+G7 -> 330 | D7: =COUNTIFS('Classificação v2'!$J$2:$J$361,"VP") -> 30 | E7: =COUNTIFS('Classificação v2'!$J$2:$J$361,"FP") -> 0 | F7: =COUNTIFS('Classificação v2'!$J$2:$J$361,"FN") -> 1 | G7: =COUNTIFS('Classificação v2'!$J$2:$J$361,"VN") -> 299 | H7: =IFERROR((D7+G7)/C7,"—") -> 0.9969697 | I7: =IFERROR(D7/(D7+E7),"—") -> 1 | J7: =IFERROR(D7/(D7+F7),"—") -> 0.96774194 | K7: =IFERROR(2*I7*J7/(I7+J7),"—") -> 0.98360656
A8: llm | B8: estrito | C8: =D8+E8+F8+G8 -> 358 | D8: =COUNTIFS('Classificação v2'!$K$2:$K$361,"VP") -> 26 | E8: =COUNTIFS('Classificação v2'!$K$2:$K$361,"FP") -> 64 | F8: =COUNTIFS('Classificação v2'!$K$2:$K$361,"FN") -> 3 | G8: =COUNTIFS('Classificação v2'!$K$2:$K$361,"VN") -> 265 | H8: =IFERROR((D8+G8)/C8,"—") -> 0.81284916 | I8: =IFERROR(D8/(D8+E8),"—") -> 0.28888889 | J8: =IFERROR(D8/(D8+F8),"—") -> 0.89655172 | K8: =IFERROR(2*I8*J8/(I8+J8),"—") -> 0.43697479
A9: llm | B9: amplo | C9: =D9+E9+F9+G9 -> 360 | D9: =COUNTIFS('Classificação v2'!$L$2:$L$361,"VP") -> 31 | E9: =COUNTIFS('Classificação v2'!$L$2:$L$361,"FP") -> 107 | F9: =COUNTIFS('Classificação v2'!$L$2:$L$361,"FN") -> 0 | G9: =COUNTIFS('Classificação v2'!$L$2:$L$361,"VN") -> 222 | H9: =IFERROR((D9+G9)/C9,"—") -> 0.70277778 | I9: =IFERROR(D9/(D9+E9),"—") -> 0.22463768 | J9: =IFERROR(D9/(D9+F9),"—") -> 1 | K9: =IFERROR(2*I9*J9/(I9+J9),"—") -> 0.36686391
A10: final | B10: estrito | C10: =D10+E10+F10+G10 -> 358 | D10: =COUNTIFS('Classificação v2'!$M$2:$M$361,"VP") -> 27 | E10: =COUNTIFS('Classificação v2'!$M$2:$M$361,"FP") -> 1 | F10: =COUNTIFS('Classificação v2'!$M$2:$M$361,"FN") -> 2 | G10: =COUNTIFS('Classificação v2'!$M$2:$M$361,"VN") -> 328 | H10: =IFERROR((D10+G10)/C10,"—") -> 0.99162011 | I10: =IFERROR(D10/(D10+E10),"—") -> 0.96428571 | J10: =IFERROR(D10/(D10+F10),"—") -> 0.93103448 | K10: =IFERROR(2*I10*J10/(I10+J10),"—") -> 0.94736842
A11: final | B11: amplo | C11: =D11+E11+F11+G11 -> 360 | D11: =COUNTIFS('Classificação v2'!$N$2:$N$361,"VP") -> 30 | E11: =COUNTIFS('Classificação v2'!$N$2:$N$361,"FP") -> 1 | F11: =COUNTIFS('Classificação v2'!$N$2:$N$361,"FN") -> 1 | G11: =COUNTIFS('Classificação v2'!$N$2:$N$361,"VN") -> 328 | H11: =IFERROR((D11+G11)/C11,"—") -> 0.99444444 | I11: =IFERROR(D11/(D11+E11),"—") -> 0.96774194 | J11: =IFERROR(D11/(D11+F11),"—") -> 0.96774194 | K11: =IFERROR(2*I11*J11/(I11+J11),"—") -> 0.96774194
A12: Python não mede o 7.7.1 (30 pares '—'); por isso n é menor nessa camada. No critério estrito, pares com esperado 'Indeterminado' ficam fora (2 pares).
A14: 2. Acurácia de status exato (acertou a categoria; gabarito com errata)
A15: Camada | B15: Pares avaliados | C15: Acertos v2 | D15: Exato v2 | E15: Acertos v1 | F15: Exato v1
A16: python | B16: =COUNT('Classificação v2'!O2:O361) -> 330 | C16: =SUM('Classificação v2'!O2:O361) -> 328 | D16: =C16/B16 -> 0.99393939 | E16: =SUM('Classificação v1'!O2:O361) -> 327 | F16: =E16/COUNT('Classificação v1'!O2:O361) -> 0.99090909
A17: llm | B17: =COUNT('Classificação v2'!P2:P361) -> 360 | C17: =SUM('Classificação v2'!P2:P361) -> 243 | D17: =C17/B17 -> 0.675 | E17: =SUM('Classificação v1'!P2:P361) -> 240 | F17: =E17/COUNT('Classificação v1'!P2:P361) -> 0.66666667
A18: final | B18: =COUNT('Classificação v2'!Q2:Q361) -> 360 | C18: =SUM('Classificação v2'!Q2:Q361) -> 357 | D18: =C18/B18 -> 0.99166667 | E18: =SUM('Classificação v1'!Q2:Q361) -> 357 | F18: =E18/COUNT('Classificação v1'!Q2:Q361) -> 0.99166667
A21: 3. Rodada v1 × v2 lado a lado (critérios estrito e amplo)
C22: v1 (antes da correção) | L22: v2 (referência)
A23: Camada | B23: Critério | C23: n | D23: VP | E23: FP | F23: FN | G23: VN | H23: Acurácia | I23: Precisão | J23: Recall | K23: F1 | L23: n | M23: VP | N23: FP | O23: FN | P23: VN | Q23: Acurácia | R23: Precisão | S23: Recall | T23: F1
A24: python | B24: estrito | C24: =D24+E24+F24+G24 -> 328 | D24: =COUNTIFS('Classificação v1'!$I$2:$I$361,"VP") -> 26 | E24: =COUNTIFS('Classificação v1'!$I$2:$I$361,"FP") -> 0 | F24: =COUNTIFS('Classificação v1'!$I$2:$I$361,"FN") -> 3 | G24: =COUNTIFS('Classificação v1'!$I$2:$I$361,"VN") -> 299 | H24: =IFERROR((D24+G24)/C24,"—") -> 0.99085366 | I24: =IFERROR(D24/(D24+E24),"—") -> 1 | J24: =IFERROR(D24/(D24+F24),"—") -> 0.89655172 | K24: =IFERROR(2*I24*J24/(I24+J24),"—") -> 0.94545455 | L24: =M24+N24+O24+P24 -> 328 | M24: =COUNTIFS('Classificação v2'!$I$2:$I$361,"VP") -> 27 | N24: =COUNTIFS('Classificação v2'!$I$2:$I$361,"FP") -> 0 | O24: =COUNTIFS('Classificação v2'!$I$2:$I$361,"FN") -> 2 | P24: =COUNTIFS('Classificação v2'!$I$2:$I$361,"VN") -> 299 | Q24: =IFERROR((M24+P24)/L24,"—") -> 0.99390244 | R24: =IFERROR(M24/(M24+N24),"—") -> 1 | S24: =IFERROR(M24/(M24+O24),"—") -> 0.93103448 | T24: =IFERROR(2*R24*S24/(R24+S24),"—") -> 0.96428571
A25: python | B25: amplo | C25: =D25+E25+F25+G25 -> 330 | D25: =COUNTIFS('Classificação v1'!$J$2:$J$361,"VP") -> 30 | E25: =COUNTIFS('Classificação v1'!$J$2:$J$361,"FP") -> 0 | F25: =COUNTIFS('Classificação v1'!$J$2:$J$361,"FN") -> 1 | G25: =COUNTIFS('Classificação v1'!$J$2:$J$361,"VN") -> 299 | H25: =IFERROR((D25+G25)/C25,"—") -> 0.9969697 | I25: =IFERROR(D25/(D25+E25),"—") -> 1 | J25: =IFERROR(D25/(D25+F25),"—") -> 0.96774194 | K25: =IFERROR(2*I25*J25/(I25+J25),"—") -> 0.98360656 | L25: =M25+N25+O25+P25 -> 330 | M25: =COUNTIFS('Classificação v2'!$J$2:$J$361,"VP") -> 30 | N25: =COUNTIFS('Classificação v2'!$J$2:$J$361,"FP") -> 0 | O25: =COUNTIFS('Classificação v2'!$J$2:$J$361,"FN") -> 1 | P25: =COUNTIFS('Classificação v2'!$J$2:$J$361,"VN") -> 299 | Q25: =IFERROR((M25+P25)/L25,"—") -> 0.9969697 | R25: =IFERROR(M25/(M25+N25),"—") -> 1 | S25: =IFERROR(M25/(M25+O25),"—") -> 0.96774194 | T25: =IFERROR(2*R25*S25/(R25+S25),"—") -> 0.98360656
A26: llm | B26: estrito | C26: =D26+E26+F26+G26 -> 358 | D26: =COUNTIFS('Classificação v1'!$K$2:$K$361,"VP") -> 26 | E26: =COUNTIFS('Classificação v1'!$K$2:$K$361,"FP") -> 64 | F26: =COUNTIFS('Classificação v1'!$K$2:$K$361,"FN") -> 3 | G26: =COUNTIFS('Classificação v1'!$K$2:$K$361,"VN") -> 265 | H26: =IFERROR((D26+G26)/C26,"—") -> 0.81284916 | I26: =IFERROR(D26/(D26+E26),"—") -> 0.28888889 | J26: =IFERROR(D26/(D26+F26),"—") -> 0.89655172 | K26: =IFERROR(2*I26*J26/(I26+J26),"—") -> 0.43697479 | L26: =M26+N26+O26+P26 -> 358 | M26: =COUNTIFS('Classificação v2'!$K$2:$K$361,"VP") -> 26 | N26: =COUNTIFS('Classificação v2'!$K$2:$K$361,"FP") -> 64 | O26: =COUNTIFS('Classificação v2'!$K$2:$K$361,"FN") -> 3 | P26: =COUNTIFS('Classificação v2'!$K$2:$K$361,"VN") -> 265 | Q26: =IFERROR((M26+P26)/L26,"—") -> 0.81284916 | R26: =IFERROR(M26/(M26+N26),"—") -> 0.28888889 | S26: =IFERROR(M26/(M26+O26),"—") -> 0.89655172 | T26: =IFERROR(2*R26*S26/(R26+S26),"—") -> 0.43697479
A27: llm | B27: amplo | C27: =D27+E27+F27+G27 -> 360 | D27: =COUNTIFS('Classificação v1'!$L$2:$L$361,"VP") -> 30 | E27: =COUNTIFS('Classificação v1'!$L$2:$L$361,"FP") -> 109 | F27: =COUNTIFS('Classificação v1'!$L$2:$L$361,"FN") -> 1 | G27: =COUNTIFS('Classificação v1'!$L$2:$L$361,"VN") -> 220 | H27: =IFERROR((D27+G27)/C27,"—") -> 0.69444444 | I27: =IFERROR(D27/(D27+E27),"—") -> 0.21582734 | J27: =IFERROR(D27/(D27+F27),"—") -> 0.96774194 | K27: =IFERROR(2*I27*J27/(I27+J27),"—") -> 0.35294118 | L27: =M27+N27+O27+P27 -> 360 | M27: =COUNTIFS('Classificação v2'!$L$2:$L$361,"VP") -> 31 | N27: =COUNTIFS('Classificação v2'!$L$2:$L$361,"FP") -> 107 | O27: =COUNTIFS('Classificação v2'!$L$2:$L$361,"FN") -> 0 | P27: =COUNTIFS('Classificação v2'!$L$2:$L$361,"VN") -> 222 | Q27: =IFERROR((M27+P27)/L27,"—") -> 0.70277778 | R27: =IFERROR(M27/(M27+N27),"—") -> 0.22463768 | S27: =IFERROR(M27/(M27+O27),"—") -> 1 | T27: =IFERROR(2*R27*S27/(R27+S27),"—") -> 0.36686391
A28: final | B28: estrito | C28: =D28+E28+F28+G28 -> 358 | D28: =COUNTIFS('Classificação v1'!$M$2:$M$361,"VP") -> 26 | E28: =COUNTIFS('Classificação v1'!$M$2:$M$361,"FP") -> 0 | F28: =COUNTIFS('Classificação v1'!$M$2:$M$361,"FN") -> 3 | G28: =COUNTIFS('Classificação v1'!$M$2:$M$361,"VN") -> 329 | H28: =IFERROR((D28+G28)/C28,"—") -> 0.99162011 | I28: =IFERROR(D28/(D28+E28),"—") -> 1 | J28: =IFERROR(D28/(D28+F28),"—") -> 0.89655172 | K28: =IFERROR(2*I28*J28/(I28+J28),"—") -> 0.94545455 | L28: =M28+N28+O28+P28 -> 358 | M28: =COUNTIFS('Classificação v2'!$M$2:$M$361,"VP") -> 27 | N28: =COUNTIFS('Classificação v2'!$M$2:$M$361,"FP") -> 1 | O28: =COUNTIFS('Classificação v2'!$M$2:$M$361,"FN") -> 2 | P28: =COUNTIFS('Classificação v2'!$M$2:$M$361,"VN") -> 328 | Q28: =IFERROR((M28+P28)/L28,"—") -> 0.99162011 | R28: =IFERROR(M28/(M28+N28),"—") -> 0.96428571 | S28: =IFERROR(M28/(M28+O28),"—") -> 0.93103448 | T28: =IFERROR(2*R28*S28/(R28+S28),"—") -> 0.94736842
A29: final | B29: amplo | C29: =D29+E29+F29+G29 -> 360 | D29: =COUNTIFS('Classificação v1'!$N$2:$N$361,"VP") -> 30 | E29: =COUNTIFS('Classificação v1'!$N$2:$N$361,"FP") -> 0 | F29: =COUNTIFS('Classificação v1'!$N$2:$N$361,"FN") -> 1 | G29: =COUNTIFS('Classificação v1'!$N$2:$N$361,"VN") -> 329 | H29: =IFERROR((D29+G29)/C29,"—") -> 0.99722222 | I29: =IFERROR(D29/(D29+E29),"—") -> 1 | J29: =IFERROR(D29/(D29+F29),"—") -> 0.96774194 | K29: =IFERROR(2*I29*J29/(I29+J29),"—") -> 0.98360656 | L29: =M29+N29+O29+P29 -> 360 | M29: =COUNTIFS('Classificação v2'!$N$2:$N$361,"VP") -> 30 | N29: =COUNTIFS('Classificação v2'!$N$2:$N$361,"FP") -> 1 | O29: =COUNTIFS('Classificação v2'!$N$2:$N$361,"FN") -> 1 | P29: =COUNTIFS('Classificação v2'!$N$2:$N$361,"VN") -> 328 | Q29: =IFERROR((M29+P29)/L29,"—") -> 0.99444444 | R29: =IFERROR(M29/(M29+N29),"—") -> 0.96774194 | S29: =IFERROR(M29/(M29+O29),"—") -> 0.96774194 | T29: =IFERROR(2*R29*S29/(R29+S29),"—") -> 0.96774194
A30: Python v1→v2: só mudou S02/7.7.2.1 (Indeterminado → Parcial), efeito da correção da altura da bacia. Diferenças na camada LLM vêm do não determinismo do modelo.
A33: 4. Análise de sensibilidade — camada final v2 sem o par W01 / 7.7.1
A34: A mutação W01 só alterou o contorno do ambiente (giro ⌀1,50 m). O LLM acusou 7.7.1 (área de transferência), que o Python não mede — o 'erro' é ambíguo: o espaço realmente ficou menor.
A35: Camada | B35: Critério | C35: n | D35: VP | E35: FP | F35: FN | G35: VN | H35: Acurácia | I35: Precisão | J35: Recall | K35: F1
A36: final sem W01/7.7.1 | B36: estrito | C36: =D36+E36+F36+G36 -> 357 | D36: =COUNTIFS('Classificação v2'!$M$2:$M$361,"VP",'Classificação v2'!$H$2:$H$361,0) -> 27 | E36: =COUNTIFS('Classificação v2'!$M$2:$M$361,"FP",'Classificação v2'!$H$2:$H$361,0) -> 0 | F36: =COUNTIFS('Classificação v2'!$M$2:$M$361,"FN",'Classificação v2'!$H$2:$H$361,0) -> 2 | G36: =COUNTIFS('Classificação v2'!$M$2:$M$361,"VN",'Classificação v2'!$H$2:$H$361,0) -> 328 | H36: =IFERROR((D36+G36)/C36,"—") -> 0.99439776 | I36: =IFERROR(D36/(D36+E36),"—") -> 1 | J36: =IFERROR(D36/(D36+F36),"—") -> 0.93103448 | K36: =IFERROR(2*I36*J36/(I36+J36),"—") -> 0.96428571
A37: final sem W01/7.7.1 | B37: amplo | C37: =D37+E37+F37+G37 -> 359 | D37: =COUNTIFS('Classificação v2'!$N$2:$N$361,"VP",'Classificação v2'!$H$2:$H$361,0) -> 30 | E37: =COUNTIFS('Classificação v2'!$N$2:$N$361,"FP",'Classificação v2'!$H$2:$H$361,0) -> 0 | F37: =COUNTIFS('Classificação v2'!$N$2:$N$361,"FN",'Classificação v2'!$H$2:$H$361,0) -> 1 | G37: =COUNTIFS('Classificação v2'!$N$2:$N$361,"VN",'Classificação v2'!$H$2:$H$361,0) -> 328 | H37: =IFERROR((D37+G37)/C37,"—") -> 0.99721448 | I37: =IFERROR(D37/(D37+E37),"—") -> 1 | J37: =IFERROR(D37/(D37+F37),"—") -> 0.96774194 | K37: =IFERROR(2*I37*J37/(I37+J37),"—") -> 0.98360656
A40: 5. O que a arquitetura híbrida ('LLM traduz, Python julga') ganha — v2, critério estrito
A41: Métrica | B41: Só LLM | C41: Final (híbrido) | D41: Diferença
A42: Precisão | B42: =I8 -> 0.28888889 | C42: =I10 -> 0.96428571 | D42: =C42-B42 -> 0.67539683
A43: Recall | B43: =J8 -> 0.89655172 | C43: =J10 -> 0.93103448 | D43: =C43-B43 -> 0.034482759
A44: F1 | B44: =K8 -> 0.43697479 | C44: =K10 -> 0.94736842 | D44: =C44-B44 -> 0.51039363
A45: Alarmes falsos (FP) | B45: =E8 -> 64 | C45: =E10 -> 1 | D45: =C45-B45 -> -63

Sheet Métricas por item
A1: Rodada v2 — métricas por item NBR (fórmulas sobre 'Classificação v2')
A3: Critério estrito
A4: Item NBR | B4: Camada | C4: n | D4: VP | E4: FP | F4: FN | G4: VN | H4: Acurácia | I4: Precisão | J4: Recall | K4: F1
A5: 4.6.6 | B5: python | C5: =D5+E5+F5+G5 -> 29 | D5: =COUNTIFS('Classificação v2'!$I$2:$I$361,"VP",'Classificação v2'!$B$2:$B$361,"4.6.6") -> 2 | E5: =COUNTIFS('Classificação v2'!$I$2:$I$361,"FP",'Classificação v2'!$B$2:$B$361,"4.6.6") -> 0 | F5: =COUNTIFS('Classificação v2'!$I$2:$I$361,"FN",'Classificação v2'!$B$2:$B$361,"4.6.6") -> 0 | G5: =COUNTIFS('Classificação v2'!$I$2:$I$361,"VN",'Classificação v2'!$B$2:$B$361,"4.6.6") -> 27 | H5: =IFERROR((D5+G5)/C5,"—") -> 1 | I5: =IFERROR(D5/(D5+E5),"—") -> 1 | J5: =IFERROR(D5/(D5+F5),"—") -> 1 | K5: =IFERROR(2*I5*J5/(I5+J5),"—") -> 1
A6: 4.6.6 | B6: llm | C6: =D6+E6+F6+G6 -> 29 | D6: =COUNTIFS('Classificação v2'!$K$2:$K$361,"VP",'Classificação v2'!$B$2:$B$361,"4.6.6") -> 0 | E6: =COUNTIFS('Classificação v2'!$K$2:$K$361,"FP",'Classificação v2'!$B$2:$B$361,"4.6.6") -> 0 | F6: =COUNTIFS('Classificação v2'!$K$2:$K$361,"FN",'Classificação v2'!$B$2:$B$361,"4.6.6") -> 2 | G6: =COUNTIFS('Classificação v2'!$K$2:$K$361,"VN",'Classificação v2'!$B$2:$B$361,"4.6.6") -> 27 | H6: =IFERROR((D6+G6)/C6,"—") -> 0.93103448 | I6: =IFERROR(D6/(D6+E6),"—") -> — | J6: =IFERROR(D6/(D6+F6),"—") -> 0 | K6: =IFERROR(2*I6*J6/(I6+J6),"—") -> —
A7: 4.6.6 | B7: final | C7: =D7+E7+F7+G7 -> 29 | D7: =COUNTIFS('Classificação v2'!$M$2:$M$361,"VP",'Classificação v2'!$B$2:$B$361,"4.6.6") -> 2 | E7: =COUNTIFS('Classificação v2'!$M$2:$M$361,"FP",'Classificação v2'!$B$2:$B$361,"4.6.6") -> 0 | F7: =COUNTIFS('Classificação v2'!$M$2:$M$361,"FN",'Classificação v2'!$B$2:$B$361,"4.6.6") -> 0 | G7: =COUNTIFS('Classificação v2'!$M$2:$M$361,"VN",'Classificação v2'!$B$2:$B$361,"4.6.6") -> 27 | H7: =IFERROR((D7+G7)/C7,"—") -> 1 | I7: =IFERROR(D7/(D7+E7),"—") -> 1 | J7: =IFERROR(D7/(D7+F7),"—") -> 1 | K7: =IFERROR(2*I7*J7/(I7+J7),"—") -> 1
A8: 5.4.3 | B8: python | C8: =D8+E8+F8+G8 -> 30 | D8: =COUNTIFS('Classificação v2'!$I$2:$I$361,"VP",'Classificação v2'!$B$2:$B$361,"5.4.3") -> 4 | E8: =COUNTIFS('Classificação v2'!$I$2:$I$361,"FP",'Classificação v2'!$B$2:$B$361,"5.4.3") -> 0 | F8: =COUNTIFS('Classificação v2'!$I$2:$I$361,"FN",'Classificação v2'!$B$2:$B$361,"5.4.3") -> 0 | G8: =COUNTIFS('Classificação v2'!$I$2:$I$361,"VN",'Classificação v2'!$B$2:$B$361,"5.4.3") -> 26 | H8: =IFERROR((D8+G8)/C8,"—") -> 1 | I8: =IFERROR(D8/(D8+E8),"—") -> 1 | J8: =IFERROR(D8/(D8+F8),"—") -> 1 | K8: =IFERROR(2*I8*J8/(I8+J8),"—") -> 1
A9: 5.4.3 | B9: llm | C9: =D9+E9+F9+G9 -> 30 | D9: =COUNTIFS('Classificação v2'!$K$2:$K$361,"VP",'Classificação v2'!$B$2:$B$361,"5.4.3") -> 4 | E9: =COUNTIFS('Classificação v2'!$K$2:$K$361,"FP",'Classificação v2'!$B$2:$B$361,"5.4.3") -> 0 | F9: =COUNTIFS('Classificação v2'!$K$2:$K$361,"FN",'Classificação v2'!$B$2:$B$361,"5.4.3") -> 0 | G9: =COUNTIFS('Classificação v2'!$K$2:$K$361,"VN",'Classificação v2'!$B$2:$B$361,"5.4.3") -> 26 | H9: =IFERROR((D9+G9)/C9,"—") -> 1 | I9: =IFERROR(D9/(D9+E9),"—") -> 1 | J9: =IFERROR(D9/(D9+F9),"—") -> 1 | K9: =IFERROR(2*I9*J9/(I9+J9),"—") -> 1
A10: 5.4.3 | B10: final | C10: =D10+E10+F10+G10 -> 30 | D10: =COUNTIFS('Classificação v2'!$M$2:$M$361,"VP",'Classificação v2'!$B$2:$B$361,"5.4.3") -> 4 | E10: =COUNTIFS('Classificação v2'!$M$2:$M$361,"FP",'Classificação v2'!$B$2:$B$361,"5.4.3") -> 0 | F10: =COUNTIFS('Classificação v2'!$M$2:$M$361,"FN",'Classificação v2'!$B$2:$B$361,"5.4.3") -> 0 | G10: =COUNTIFS('Classificação v2'!$M$2:$M$361,"VN",'Classificação v2'!$B$2:$B$361,"5.4.3") -> 26 | H10: =IFERROR((D10+G10)/C10,"—") -> 1 | I10: =IFERROR(D10/(D10+E10),"—") -> 1 | J10: =IFERROR(D10/(D10+F10),"—") -> 1 | K10: =IFERROR(2*I10*J10/(I10+J10),"—") -> 1
A11: 6.3.4 | B11: python | C11: =D11+E11+F11+G11 -> 29 | D11: =COUNTIFS('Classificação v2'!$I$2:$I$361,"VP",'Classificação v2'!$B$2:$B$361,"6.3.4") -> 2 | E11: =COUNTIFS('Classificação v2'!$I$2:$I$361,"FP",'Classificação v2'!$B$2:$B$361,"6.3.4") -> 0 | F11: =COUNTIFS('Classificação v2'!$I$2:$I$361,"FN",'Classificação v2'!$B$2:$B$361,"6.3.4") -> 0 | G11: =COUNTIFS('Classificação v2'!$I$2:$I$361,"VN",'Classificação v2'!$B$2:$B$361,"6.3.4") -> 27 | H11: =IFERROR((D11+G11)/C11,"—") -> 1 | I11: =IFERROR(D11/(D11+E11),"—") -> 1 | J11: =IFERROR(D11/(D11+F11),"—") -> 1 | K11: =IFERROR(2*I11*J11/(I11+J11),"—") -> 1
A12: 6.3.4 | B12: llm | C12: =D12+E12+F12+G12 -> 29 | D12: =COUNTIFS('Classificação v2'!$K$2:$K$361,"VP",'Classificação v2'!$B$2:$B$361,"6.3.4") -> 2 | E12: =COUNTIFS('Classificação v2'!$K$2:$K$361,"FP",'Classificação v2'!$B$2:$B$361,"6.3.4") -> 1 | F12: =COUNTIFS('Classificação v2'!$K$2:$K$361,"FN",'Classificação v2'!$B$2:$B$361,"6.3.4") -> 0 | G12: =COUNTIFS('Classificação v2'!$K$2:$K$361,"VN",'Classificação v2'!$B$2:$B$361,"6.3.4") -> 26 | H12: =IFERROR((D12+G12)/C12,"—") -> 0.96551724 | I12: =IFERROR(D12/(D12+E12),"—") -> 0.66666667 | J12: =IFERROR(D12/(D12+F12),"—") -> 1 | K12: =IFERROR(2*I12*J12/(I12+J12),"—") -> 0.8
A13: 6.3.4 | B13: final | C13: =D13+E13+F13+G13 -> 29 | D13: =COUNTIFS('Classificação v2'!$M$2:$M$361,"VP",'Classificação v2'!$B$2:$B$361,"6.3.4") -> 2 | E13: =COUNTIFS('Classificação v2'!$M$2:$M$361,"FP",'Classificação v2'!$B$2:$B$361,"6.3.4") -> 0 | F13: =COUNTIFS('Classificação v2'!$M$2:$M$361,"FN",'Classificação v2'!$B$2:$B$361,"6.3.4") -> 0 | G13: =COUNTIFS('Classificação v2'!$M$2:$M$361,"VN",'Classificação v2'!$B$2:$B$361,"6.3.4") -> 27 | H13: =IFERROR((D13+G13)/C13,"—") -> 1 | I13: =IFERROR(D13/(D13+E13),"—") -> 1 | J13: =IFERROR(D13/(D13+F13),"—") -> 1 | K13: =IFERROR(2*I13*J13/(I13+J13),"—") -> 1
A14: 6.6 | B14: python | C14: =D14+E14+F14+G14 -> 30 | D14: =COUNTIFS('Classificação v2'!$I$2:$I$361,"VP",'Classificação v2'!$B$2:$B$361,"6.6") -> 3 | E14: =COUNTIFS('Classificação v2'!$I$2:$I$361,"FP",'Classificação v2'!$B$2:$B$361,"6.6") -> 0 | F14: =COUNTIFS('Classificação v2'!$I$2:$I$361,"FN",'Classificação v2'!$B$2:$B$361,"6.6") -> 0 | G14: =COUNTIFS('Classificação v2'!$I$2:$I$361,"VN",'Classificação v2'!$B$2:$B$361,"6.6") -> 27 | H14: =IFERROR((D14+G14)/C14,"—") -> 1 | I14: =IFERROR(D14/(D14+E14),"—") -> 1 | J14: =IFERROR(D14/(D14+F14),"—") -> 1 | K14: =IFERROR(2*I14*J14/(I14+J14),"—") -> 1
A15: 6.6 | B15: llm | C15: =D15+E15+F15+G15 -> 30 | D15: =COUNTIFS('Classificação v2'!$K$2:$K$361,"VP",'Classificação v2'!$B$2:$B$361,"6.6") -> 3 | E15: =COUNTIFS('Classificação v2'!$K$2:$K$361,"FP",'Classificação v2'!$B$2:$B$361,"6.6") -> 14 | F15: =COUNTIFS('Classificação v2'!$K$2:$K$361,"FN",'Classificação v2'!$B$2:$B$361,"6.6") -> 0 | G15: =COUNTIFS('Classificação v2'!$K$2:$K$361,"VN",'Classificação v2'!$B$2:$B$361,"6.6") -> 13 | H15: =IFERROR((D15+G15)/C15,"—") -> 0.53333333 | I15: =IFERROR(D15/(D15+E15),"—") -> 0.17647059 | J15: =IFERROR(D15/(D15+F15),"—") -> 1 | K15: =IFERROR(2*I15*J15/(I15+J15),"—") -> 0.3
A16: 6.6 | B16: final | C16: =D16+E16+F16+G16 -> 30 | D16: =COUNTIFS('Classificação v2'!$M$2:$M$361,"VP",'Classificação v2'!$B$2:$B$361,"6.6") -> 3 | E16: =COUNTIFS('Classificação v2'!$M$2:$M$361,"FP",'Classificação v2'!$B$2:$B$361,"6.6") -> 0 | F16: =COUNTIFS('Classificação v2'!$M$2:$M$361,"FN",'Classificação v2'!$B$2:$B$361,"6.6") -> 0 | G16: =COUNTIFS('Classificação v2'!$M$2:$M$361,"VN",'Classificação v2'!$B$2:$B$361,"6.6") -> 27 | H16: =IFERROR((D16+G16)/C16,"—") -> 1 | I16: =IFERROR(D16/(D16+E16),"—") -> 1 | J16: =IFERROR(D16/(D16+F16),"—") -> 1 | K16: =IFERROR(2*I16*J16/(I16+J16),"—") -> 1
A17: 6.11.1 | B17: python | C17: =D17+E17+F17+G17 -> 30 | D17: =COUNTIFS('Classificação v2'!$I$2:$I$361,"VP",'Classificação v2'!$B$2:$B$361,"6.11.1") -> 1 | E17: =COUNTIFS('Classificação v2'!$I$2:$I$361,"FP",'Classificação v2'!$B$2:$B$361,"6.11.1") -> 0 | F17: =COUNTIFS('Classificação v2'!$I$2:$I$361,"FN",'Classificação v2'!$B$2:$B$361,"6.11.1") -> 0 | G17: =COUNTIFS('Classificação v2'!$I$2:$I$361,"VN",'Classificação v2'!$B$2:$B$361,"6.11.1") -> 29 | H17: =IFERROR((D17+G17)/C17,"—") -> 1 | I17: =IFERROR(D17/(D17+E17),"—") -> 1 | J17: =IFERROR(D17/(D17+F17),"—") -> 1 | K17: =IFERROR(2*I17*J17/(I17+J17),"—") -> 1
A18: 6.11.1 | B18: llm | C18: =D18+E18+F18+G18 -> 30 | D18: =COUNTIFS('Classificação v2'!$K$2:$K$361,"VP",'Classificação v2'!$B$2:$B$361,"6.11.1") -> 1 | E18: =COUNTIFS('Classificação v2'!$K$2:$K$361,"FP",'Classificação v2'!$B$2:$B$361,"6.11.1") -> 0 | F18: =COUNTIFS('Classificação v2'!$K$2:$K$361,"FN",'Classificação v2'!$B$2:$B$361,"6.11.1") -> 0 | G18: =COUNTIFS('Classificação v2'!$K$2:$K$361,"VN",'Classificação v2'!$B$2:$B$361,"6.11.1") -> 29 | H18: =IFERROR((D18+G18)/C18,"—") -> 1 | I18: =IFERROR(D18/(D18+E18),"—") -> 1 | J18: =IFERROR(D18/(D18+F18),"—") -> 1 | K18: =IFERROR(2*I18*J18/(I18+J18),"—") -> 1
A19: 6.11.1 | B19: final | C19: =D19+E19+F19+G19 -> 30 | D19: =COUNTIFS('Classificação v2'!$M$2:$M$361,"VP",'Classificação v2'!$B$2:$B$361,"6.11.1") -> 1 | E19: =COUNTIFS('Classificação v2'!$M$2:$M$361,"FP",'Classificação v2'!$B$2:$B$361,"6.11.1") -> 0 | F19: =COUNTIFS('Classificação v2'!$M$2:$M$361,"FN",'Classificação v2'!$B$2:$B$361,"6.11.1") -> 0 | G19: =COUNTIFS('Classificação v2'!$M$2:$M$361,"VN",'Classificação v2'!$B$2:$B$361,"6.11.1") -> 29 | H19: =IFERROR((D19+G19)/C19,"—") -> 1 | I19: =IFERROR(D19/(D19+E19),"—") -> 1 | J19: =IFERROR(D19/(D19+F19),"—") -> 1 | K19: =IFERROR(2*I19*J19/(I19+J19),"—") -> 1
A20: 6.11.2 | B20: python | C20: =D20+E20+F20+G20 -> 30 | D20: =COUNTIFS('Classificação v2'!$I$2:$I$361,"VP",'Classificação v2'!$B$2:$B$361,"6.11.2") -> 4 | E20: =COUNTIFS('Classificação v2'!$I$2:$I$361,"FP",'Classificação v2'!$B$2:$B$361,"6.11.2") -> 0 | F20: =COUNTIFS('Classificação v2'!$I$2:$I$361,"FN",'Classificação v2'!$B$2:$B$361,"6.11.2") -> 0 | G20: =COUNTIFS('Classificação v2'!$I$2:$I$361,"VN",'Classificação v2'!$B$2:$B$361,"6.11.2") -> 26 | H20: =IFERROR((D20+G20)/C20,"—") -> 1 | I20: =IFERROR(D20/(D20+E20),"—") -> 1 | J20: =IFERROR(D20/(D20+F20),"—") -> 1 | K20: =IFERROR(2*I20*J20/(I20+J20),"—") -> 1
A21: 6.11.2 | B21: llm | C21: =D21+E21+F21+G21 -> 30 | D21: =COUNTIFS('Classificação v2'!$K$2:$K$361,"VP",'Classificação v2'!$B$2:$B$361,"6.11.2") -> 4 | E21: =COUNTIFS('Classificação v2'!$K$2:$K$361,"FP",'Classificação v2'!$B$2:$B$361,"6.11.2") -> 0 | F21: =COUNTIFS('Classificação v2'!$K$2:$K$361,"FN",'Classificação v2'!$B$2:$B$361,"6.11.2") -> 0 | G21: =COUNTIFS('Classificação v2'!$K$2:$K$361,"VN",'Classificação v2'!$B$2:$B$361,"6.11.2") -> 26 | H21: =IFERROR((D21+G21)/C21,"—") -> 1 | I21: =IFERROR(D21/(D21+E21),"—") -> 1 | J21: =IFERROR(D21/(D21+F21),"—") -> 1 | K21: =IFERROR(2*I21*J21/(I21+J21),"—") -> 1
A22: 6.11.2 | B22: final | C22: =D22+E22+F22+G22 -> 30 | D22: =COUNTIFS('Classificação v2'!$M$2:$M$361,"VP",'Classificação v2'!$B$2:$B$361,"6.11.2") -> 4 | E22: =COUNTIFS('Classificação v2'!$M$2:$M$361,"FP",'Classificação v2'!$B$2:$B$361,"6.11.2") -> 0 | F22: =COUNTIFS('Classificação v2'!$M$2:$M$361,"FN",'Classificação v2'!$B$2:$B$361,"6.11.2") -> 0 | G22: =COUNTIFS('Classificação v2'!$M$2:$M$361,"VN",'Classificação v2'!$B$2:$B$361,"6.11.2") -> 26 | H22: =IFERROR((D22+G22)/C22,"—") -> 1 | I22: =IFERROR(D22/(D22+E22),"—") -> 1 | J22: =IFERROR(D22/(D22+F22),"—") -> 1 | K22: =IFERROR(2*I22*J22/(I22+J22),"—") -> 1
A23: 6.11.3 | B23: python | C23: =D23+E23+F23+G23 -> 30 | D23: =COUNTIFS('Classificação v2'!$I$2:$I$361,"VP",'Classificação v2'!$B$2:$B$361,"6.11.3") -> 1 | E23: =COUNTIFS('Classificação v2'!$I$2:$I$361,"FP",'Classificação v2'!$B$2:$B$361,"6.11.3") -> 0 | F23: =COUNTIFS('Classificação v2'!$I$2:$I$361,"FN",'Classificação v2'!$B$2:$B$361,"6.11.3") -> 0 | G23: =COUNTIFS('Classificação v2'!$I$2:$I$361,"VN",'Classificação v2'!$B$2:$B$361,"6.11.3") -> 29 | H23: =IFERROR((D23+G23)/C23,"—") -> 1 | I23: =IFERROR(D23/(D23+E23),"—") -> 1 | J23: =IFERROR(D23/(D23+F23),"—") -> 1 | K23: =IFERROR(2*I23*J23/(I23+J23),"—") -> 1
A24: 6.11.3 | B24: llm | C24: =D24+E24+F24+G24 -> 30 | D24: =COUNTIFS('Classificação v2'!$K$2:$K$361,"VP",'Classificação v2'!$B$2:$B$361,"6.11.3") -> 1 | E24: =COUNTIFS('Classificação v2'!$K$2:$K$361,"FP",'Classificação v2'!$B$2:$B$361,"6.11.3") -> 1 | F24: =COUNTIFS('Classificação v2'!$K$2:$K$361,"FN",'Classificação v2'!$B$2:$B$361,"6.11.3") -> 0 | G24: =COUNTIFS('Classificação v2'!$K$2:$K$361,"VN",'Classificação v2'!$B$2:$B$361,"6.11.3") -> 28 | H24: =IFERROR((D24+G24)/C24,"—") -> 0.96666667 | I24: =IFERROR(D24/(D24+E24),"—") -> 0.5 | J24: =IFERROR(D24/(D24+F24),"—") -> 1 | K24: =IFERROR(2*I24*J24/(I24+J24),"—") -> 0.66666667
A25: 6.11.3 | B25: final | C25: =D25+E25+F25+G25 -> 30 | D25: =COUNTIFS('Classificação v2'!$M$2:$M$361,"VP",'Classificação v2'!$B$2:$B$361,"6.11.3") -> 1 | E25: =COUNTIFS('Classificação v2'!$M$2:$M$361,"FP",'Classificação v2'!$B$2:$B$361,"6.11.3") -> 0 | F25: =COUNTIFS('Classificação v2'!$M$2:$M$361,"FN",'Classificação v2'!$B$2:$B$361,"6.11.3") -> 0 | G25: =COUNTIFS('Classificação v2'!$M$2:$M$361,"VN",'Classificação v2'!$B$2:$B$361,"6.11.3") -> 29 | H25: =IFERROR((D25+G25)/C25,"—") -> 1 | I25: =IFERROR(D25/(D25+E25),"—") -> 1 | J25: =IFERROR(D25/(D25+F25),"—") -> 1 | K25: =IFERROR(2*I25*J25/(I25+J25),"—") -> 1
A26: 7.5 | B26: python | C26: =D26+E26+F26+G26 -> 30 | D26: =COUNTIFS('Classificação v2'!$I$2:$I$361,"VP",'Classificação v2'!$B$2:$B$361,"7.5") -> 1 | E26: =COUNTIFS('Classificação v2'!$I$2:$I$361,"FP",'Classificação v2'!$B$2:$B$361,"7.5") -> 0 | F26: =COUNTIFS('Classificação v2'!$I$2:$I$361,"FN",'Classificação v2'!$B$2:$B$361,"7.5") -> 0 | G26: =COUNTIFS('Classificação v2'!$I$2:$I$361,"VN",'Classificação v2'!$B$2:$B$361,"7.5") -> 29 | H26: =IFERROR((D26+G26)/C26,"—") -> 1 | I26: =IFERROR(D26/(D26+E26),"—") -> 1 | J26: =IFERROR(D26/(D26+F26),"—") -> 1 | K26: =IFERROR(2*I26*J26/(I26+J26),"—") -> 1
A27: 7.5 | B27: llm | C27: =D27+E27+F27+G27 -> 30 | D27: =COUNTIFS('Classificação v2'!$K$2:$K$361,"VP",'Classificação v2'!$B$2:$B$361,"7.5") -> 1 | E27: =COUNTIFS('Classificação v2'!$K$2:$K$361,"FP",'Classificação v2'!$B$2:$B$361,"7.5") -> 0 | F27: =COUNTIFS('Classificação v2'!$K$2:$K$361,"FN",'Classificação v2'!$B$2:$B$361,"7.5") -> 0 | G27: =COUNTIFS('Classificação v2'!$K$2:$K$361,"VN",'Classificação v2'!$B$2:$B$361,"7.5") -> 29 | H27: =IFERROR((D27+G27)/C27,"—") -> 1 | I27: =IFERROR(D27/(D27+E27),"—") -> 1 | J27: =IFERROR(D27/(D27+F27),"—") -> 1 | K27: =IFERROR(2*I27*J27/(I27+J27),"—") -> 1
A28: 7.5 | B28: final | C28: =D28+E28+F28+G28 -> 30 | D28: =COUNTIFS('Classificação v2'!$M$2:$M$361,"VP",'Classificação v2'!$B$2:$B$361,"7.5") -> 1 | E28: =COUNTIFS('Classificação v2'!$M$2:$M$361,"FP",'Classificação v2'!$B$2:$B$361,"7.5") -> 0 | F28: =COUNTIFS('Classificação v2'!$M$2:$M$361,"FN",'Classificação v2'!$B$2:$B$361,"7.5") -> 0 | G28: =COUNTIFS('Classificação v2'!$M$2:$M$361,"VN",'Classificação v2'!$B$2:$B$361,"7.5") -> 29 | H28: =IFERROR((D28+G28)/C28,"—") -> 1 | I28: =IFERROR(D28/(D28+E28),"—") -> 1 | J28: =IFERROR(D28/(D28+F28),"—") -> 1 | K28: =IFERROR(2*I28*J28/(I28+J28),"—") -> 1
A29: 7.6-7.8 | B29: python | C29: =D29+E29+F29+G29 -> 30 | D29: =COUNTIFS('Classificação v2'!$I$2:$I$361,"VP",'Classificação v2'!$B$2:$B$361,"7.6-7.8") -> 7 | E29: =COUNTIFS('Classificação v2'!$I$2:$I$361,"FP",'Classificação v2'!$B$2:$B$361,"7.6-7.8") -> 0 | F29: =COUNTIFS('Classificação v2'!$I$2:$I$361,"FN",'Classificação v2'!$B$2:$B$361,"7.6-7.8") -> 1 | G29: =COUNTIFS('Classificação v2'!$I$2:$I$361,"VN",'Classificação v2'!$B$2:$B$361,"7.6-7.8") -> 22 | H29: =IFERROR((D29+G29)/C29,"—") -> 0.96666667 | I29: =IFERROR(D29/(D29+E29),"—") -> 1 | J29: =IFERROR(D29/(D29+F29),"—") -> 0.875 | K29: =IFERROR(2*I29*J29/(I29+J29),"—") -> 0.93333333
A30: 7.6-7.8 | B30: llm | C30: =D30+E30+F30+G30 -> 30 | D30: =COUNTIFS('Classificação v2'!$K$2:$K$361,"VP",'Classificação v2'!$B$2:$B$361,"7.6-7.8") -> 8 | E30: =COUNTIFS('Classificação v2'!$K$2:$K$361,"FP",'Classificação v2'!$B$2:$B$361,"7.6-7.8") -> 19 | F30: =COUNTIFS('Classificação v2'!$K$2:$K$361,"FN",'Classificação v2'!$B$2:$B$361,"7.6-7.8") -> 0 | G30: =COUNTIFS('Classificação v2'!$K$2:$K$361,"VN",'Classificação v2'!$B$2:$B$361,"7.6-7.8") -> 3 | H30: =IFERROR((D30+G30)/C30,"—") -> 0.36666667 | I30: =IFERROR(D30/(D30+E30),"—") -> 0.2962963 | J30: =IFERROR(D30/(D30+F30),"—") -> 1 | K30: =IFERROR(2*I30*J30/(I30+J30),"—") -> 0.45714286
A31: 7.6-7.8 | B31: final | C31: =D31+E31+F31+G31 -> 30 | D31: =COUNTIFS('Classificação v2'!$M$2:$M$361,"VP",'Classificação v2'!$B$2:$B$361,"7.6-7.8") -> 7 | E31: =COUNTIFS('Classificação v2'!$M$2:$M$361,"FP",'Classificação v2'!$B$2:$B$361,"7.6-7.8") -> 0 | F31: =COUNTIFS('Classificação v2'!$M$2:$M$361,"FN",'Classificação v2'!$B$2:$B$361,"7.6-7.8") -> 1 | G31: =COUNTIFS('Classificação v2'!$M$2:$M$361,"VN",'Classificação v2'!$B$2:$B$361,"7.6-7.8") -> 22 | H31: =IFERROR((D31+G31)/C31,"—") -> 0.96666667 | I31: =IFERROR(D31/(D31+E31),"—") -> 1 | J31: =IFERROR(D31/(D31+F31),"—") -> 0.875 | K31: =IFERROR(2*I31*J31/(I31+J31),"—") -> 0.93333333
A32: 7.7.1 | B32: python | C32: =D32+E32+F32+G32 -> 0 | D32: =COUNTIFS('Classificação v2'!$I$2:$I$361,"VP",'Classificação v2'!$B$2:$B$361,"7.7.1") -> 0 | E32: =COUNTIFS('Classificação v2'!$I$2:$I$361,"FP",'Classificação v2'!$B$2:$B$361,"7.7.1") -> 0 | F32: =COUNTIFS('Classificação v2'!$I$2:$I$361,"FN",'Classificação v2'!$B$2:$B$361,"7.7.1") -> 0 | G32: =COUNTIFS('Classificação v2'!$I$2:$I$361,"VN",'Classificação v2'!$B$2:$B$361,"7.7.1") -> 0 | H32: =IFERROR((D32+G32)/C32,"—") -> — | I32: =IFERROR(D32/(D32+E32),"—") -> — | J32: =IFERROR(D32/(D32+F32),"—") -> — | K32: =IFERROR(2*I32*J32/(I32+J32),"—") -> —
A33: 7.7.1 | B33: llm | C33: =D33+E33+F33+G33 -> 30 | D33: =COUNTIFS('Classificação v2'!$K$2:$K$361,"VP",'Classificação v2'!$B$2:$B$361,"7.7.1") -> 0 | E33: =COUNTIFS('Classificação v2'!$K$2:$K$361,"FP",'Classificação v2'!$B$2:$B$361,"7.7.1") -> 1 | F33: =COUNTIFS('Classificação v2'!$K$2:$K$361,"FN",'Classificação v2'!$B$2:$B$361,"7.7.1") -> 0 | G33: =COUNTIFS('Classificação v2'!$K$2:$K$361,"VN",'Classificação v2'!$B$2:$B$361,"7.7.1") -> 29 | H33: =IFERROR((D33+G33)/C33,"—") -> 0.96666667 | I33: =IFERROR(D33/(D33+E33),"—") -> 0 | J33: =IFERROR(D33/(D33+F33),"—") -> — | K33: =IFERROR(2*I33*J33/(I33+J33),"—") -> —
A34: 7.7.1 | B34: final | C34: =D34+E34+F34+G34 -> 30 | D34: =COUNTIFS('Classificação v2'!$M$2:$M$361,"VP",'Classificação v2'!$B$2:$B$361,"7.7.1") -> 0 | E34: =COUNTIFS('Classificação v2'!$M$2:$M$361,"FP",'Classificação v2'!$B$2:$B$361,"7.7.1") -> 1 | F34: =COUNTIFS('Classificação v2'!$M$2:$M$361,"FN",'Classificação v2'!$B$2:$B$361,"7.7.1") -> 0 | G34: =COUNTIFS('Classificação v2'!$M$2:$M$361,"VN",'Classificação v2'!$B$2:$B$361,"7.7.1") -> 29 | H34: =IFERROR((D34+G34)/C34,"—") -> 0.96666667 | I34: =IFERROR(D34/(D34+E34),"—") -> 0 | J34: =IFERROR(D34/(D34+F34),"—") -> — | K34: =IFERROR(2*I34*J34/(I34+J34),"—") -> —
A35: 7.7.2.1 | B35: python | C35: =D35+E35+F35+G35 -> 30 | D35: =COUNTIFS('Classificação v2'!$I$2:$I$361,"VP",'Classificação v2'!$B$2:$B$361,"7.7.2.1") -> 1 | E35: =COUNTIFS('Classificação v2'!$I$2:$I$361,"FP",'Classificação v2'!$B$2:$B$361,"7.7.2.1") -> 0 | F35: =COUNTIFS('Classificação v2'!$I$2:$I$361,"FN",'Classificação v2'!$B$2:$B$361,"7.7.2.1") -> 1 | G35: =COUNTIFS('Classificação v2'!$I$2:$I$361,"VN",'Classificação v2'!$B$2:$B$361,"7.7.2.1") -> 28 | H35: =IFERROR((D35+G35)/C35,"—") -> 0.96666667 | I35: =IFERROR(D35/(D35+E35),"—") -> 1 | J35: =IFERROR(D35/(D35+F35),"—") -> 0.5 | K35: =IFERROR(2*I35*J35/(I35+J35),"—") -> 0.66666667
A36: 7.7.2.1 | B36: llm | C36: =D36+E36+F36+G36 -> 30 | D36: =COUNTIFS('Classificação v2'!$K$2:$K$361,"VP",'Classificação v2'!$B$2:$B$361,"7.7.2.1") -> 1 | E36: =COUNTIFS('Classificação v2'!$K$2:$K$361,"FP",'Classificação v2'!$B$2:$B$361,"7.7.2.1") -> 28 | F36: =COUNTIFS('Classificação v2'!$K$2:$K$361,"FN",'Classificação v2'!$B$2:$B$361,"7.7.2.1") -> 1 | G36: =COUNTIFS('Classificação v2'!$K$2:$K$361,"VN",'Classificação v2'!$B$2:$B$361,"7.7.2.1") -> 0 | H36: =IFERROR((D36+G36)/C36,"—") -> 0.033333333 | I36: =IFERROR(D36/(D36+E36),"—") -> 0.034482759 | J36: =IFERROR(D36/(D36+F36),"—") -> 0.5 | K36: =IFERROR(2*I36*J36/(I36+J36),"—") -> 0.064516129
A37: 7.7.2.1 | B37: final | C37: =D37+E37+F37+G37 -> 30 | D37: =COUNTIFS('Classificação v2'!$M$2:$M$361,"VP",'Classificação v2'!$B$2:$B$361,"7.7.2.1") -> 1 | E37: =COUNTIFS('Classificação v2'!$M$2:$M$361,"FP",'Classificação v2'!$B$2:$B$361,"7.7.2.1") -> 0 | F37: =COUNTIFS('Classificação v2'!$M$2:$M$361,"FN",'Classificação v2'!$B$2:$B$361,"7.7.2.1") -> 1 | G37: =COUNTIFS('Classificação v2'!$M$2:$M$361,"VN",'Classificação v2'!$B$2:$B$361,"7.7.2.1") -> 28 | H37: =IFERROR((D37+G37)/C37,"—") -> 0.96666667 | I37: =IFERROR(D37/(D37+E37),"—") -> 1 | J37: =IFERROR(D37/(D37+F37),"—") -> 0.5 | K37: =IFERROR(2*I37*J37/(I37+J37),"—") -> 0.66666667
A38: 7.8 | B38: python | C38: =D38+E38+F38+G38 -> 30 | D38: =COUNTIFS('Classificação v2'!$I$2:$I$361,"VP",'Classificação v2'!$B$2:$B$361,"7.8") -> 1 | E38: =COUNTIFS('Classificação v2'!$I$2:$I$361,"FP",'Classificação v2'!$B$2:$B$361,"7.8") -> 0 | F38: =COUNTIFS('Classificação v2'!$I$2:$I$361,"FN",'Classificação v2'!$B$2:$B$361,"7.8") -> 0 | G38: =COUNTIFS('Classificação v2'!$I$2:$I$361,"VN",'Classificação v2'!$B$2:$B$361,"7.8") -> 29 | H38: =IFERROR((D38+G38)/C38,"—") -> 1 | I38: =IFERROR(D38/(D38+E38),"—") -> 1 | J38: =IFERROR(D38/(D38+F38),"—") -> 1 | K38: =IFERROR(2*I38*J38/(I38+J38),"—") -> 1
A39: 7.8 | B39: llm | C39: =D39+E39+F39+G39 -> 30 | D39: =COUNTIFS('Classificação v2'!$K$2:$K$361,"VP",'Classificação v2'!$B$2:$B$361,"7.8") -> 1 | E39: =COUNTIFS('Classificação v2'!$K$2:$K$361,"FP",'Classificação v2'!$B$2:$B$361,"7.8") -> 0 | F39: =COUNTIFS('Classificação v2'!$K$2:$K$361,"FN",'Classificação v2'!$B$2:$B$361,"7.8") -> 0 | G39: =COUNTIFS('Classificação v2'!$K$2:$K$361,"VN",'Classificação v2'!$B$2:$B$361,"7.8") -> 29 | H39: =IFERROR((D39+G39)/C39,"—") -> 1 | I39: =IFERROR(D39/(D39+E39),"—") -> 1 | J39: =IFERROR(D39/(D39+F39),"—") -> 1 | K39: =IFERROR(2*I39*J39/(I39+J39),"—") -> 1
A40: 7.8 | B40: final | C40: =D40+E40+F40+G40 -> 30 | D40: =COUNTIFS('Classificação v2'!$M$2:$M$361,"VP",'Classificação v2'!$B$2:$B$361,"7.8") -> 1 | E40: =COUNTIFS('Classificação v2'!$M$2:$M$361,"FP",'Classificação v2'!$B$2:$B$361,"7.8") -> 0 | F40: =COUNTIFS('Classificação v2'!$M$2:$M$361,"FN",'Classificação v2'!$B$2:$B$361,"7.8") -> 0 | G40: =COUNTIFS('Classificação v2'!$M$2:$M$361,"VN",'Classificação v2'!$B$2:$B$361,"7.8") -> 29 | H40: =IFERROR((D40+G40)/C40,"—") -> 1 | I40: =IFERROR(D40/(D40+E40),"—") -> 1 | J40: =IFERROR(D40/(D40+F40),"—") -> 1 | K40: =IFERROR(2*I40*J40/(I40+J40),"—") -> 1
A43: Critério amplo
...

Sheet Alarmes falsos LLM
A1: Onde o LLM sozinho erra — falsos positivos (FP) e negativos (FN) por item
A2: Contagens por CONT.SES. Em todos esses pares a camada final (Python) corrige o LLM, exceto W01/7.7.1 (item que o Python não mede).
A4: Item NBR | B4: FP estrito v1 | C4: FP estrito v2 | D4: FP amplo v1 | E4: FP amplo v2 | F4: FN estrito v2 | G4: FP final v2 (amplo) | H4: Causa provável (LLM)
A5: 4.6.6 | B5: =COUNTIFS('Classificação v1'!$K$2:$K$361,"FP",'Classificação v1'!$B$2:$B$361,"4.6.6") -> 0 | C5: =COUNTIFS('Classificação v2'!$K$2:$K$361,"FP",'Classificação v2'!$B$2:$B$361,"4.6.6") -> 0 | D5: =COUNTIFS('Classificação v1'!$L$2:$L$361,"FP",'Classificação v1'!$B$2:$B$361,"4.6.6") -> 26 | E5: =COUNTIFS('Classificação v2'!$L$2:$L$361,"FP",'Classificação v2'!$B$2:$B$361,"4.6.6") -> 27 | F5: =COUNTIFS('Classificação v2'!$K$2:$K$361,"FN",'Classificação v2'!$B$2:$B$361,"4.6.6") -> 2 | G5: =COUNTIFS('Classificação v2'!$N$2:$N$361,"FP",'Classificação v2'!$B$2:$B$361,"4.6.6") -> 0 | H5: Maçaneta tipo alavanca está nos Psets do TIPO da porta, que o prompt não inclui → Indeterminado.
A6: 5.4.3 | B6: =COUNTIFS('Classificação v1'!$K$2:$K$361,"FP",'Classificação v1'!$B$2:$B$361,"5.4.3") -> 0 | C6: =COUNTIFS('Classificação v2'!$K$2:$K$361,"FP",'Classificação v2'!$B$2:$B$361,"5.4.3") -> 0 | D6: =COUNTIFS('Classificação v1'!$L$2:$L$361,"FP",'Classificação v1'!$B$2:$B$361,"5.4.3") -> 0 | E6: =COUNTIFS('Classificação v2'!$L$2:$L$361,"FP",'Classificação v2'!$B$2:$B$361,"5.4.3") -> 0 | F6: =COUNTIFS('Classificação v2'!$K$2:$K$361,"FN",'Classificação v2'!$B$2:$B$361,"5.4.3") -> 0 | G6: =COUNTIFS('Classificação v2'!$N$2:$N$361,"FP",'Classificação v2'!$B$2:$B$361,"5.4.3") -> 0
A7: 6.3.4 | B7: =COUNTIFS('Classificação v1'!$K$2:$K$361,"FP",'Classificação v1'!$B$2:$B$361,"6.3.4") -> 0 | C7: =COUNTIFS('Classificação v2'!$K$2:$K$361,"FP",'Classificação v2'!$B$2:$B$361,"6.3.4") -> 1 | D7: =COUNTIFS('Classificação v1'!$L$2:$L$361,"FP",'Classificação v1'!$B$2:$B$361,"6.3.4") -> 19 | E7: =COUNTIFS('Classificação v2'!$L$2:$L$361,"FP",'Classificação v2'!$B$2:$B$361,"6.3.4") -> 17 | F7: =COUNTIFS('Classificação v2'!$K$2:$K$361,"FN",'Classificação v2'!$B$2:$B$361,"6.3.4") -> 0 | G7: =COUNTIFS('Classificação v2'!$N$2:$N$361,"FP",'Classificação v2'!$B$2:$B$361,"6.3.4") -> 0 | H7: Desnível de 5 mm no piso: o LLM hesita entre tolerância e falha → Indeterminado.
A8: 6.6 | B8: =COUNTIFS('Classificação v1'!$K$2:$K$361,"FP",'Classificação v1'!$B$2:$B$361,"6.6") -> 14 | C8: =COUNTIFS('Classificação v2'!$K$2:$K$361,"FP",'Classificação v2'!$B$2:$B$361,"6.6") -> 14 | D8: =COUNTIFS('Classificação v1'!$L$2:$L$361,"FP",'Classificação v1'!$B$2:$B$361,"6.6") -> 14 | E8: =COUNTIFS('Classificação v2'!$L$2:$L$361,"FP",'Classificação v2'!$B$2:$B$361,"6.6") -> 14 | F8: =COUNTIFS('Classificação v2'!$K$2:$K$361,"FN",'Classificação v2'!$B$2:$B$361,"6.6") -> 0 | G8: =COUNTIFS('Classificação v2'!$N$2:$N$361,"FP",'Classificação v2'!$B$2:$B$361,"6.6") -> 0 | H8: Inclinação calculada pelo Python (laje inclinada); o LLM às vezes não reconhece a rampa.
A9: 6.11.1 | B9: =COUNTIFS('Classificação v1'!$K$2:$K$361,"FP",'Classificação v1'!$B$2:$B$361,"6.11.1") -> 0 | C9: =COUNTIFS('Classificação v2'!$K$2:$K$361,"FP",'Classificação v2'!$B$2:$B$361,"6.11.1") -> 0 | D9: =COUNTIFS('Classificação v1'!$L$2:$L$361,"FP",'Classificação v1'!$B$2:$B$361,"6.11.1") -> 0 | E9: =COUNTIFS('Classificação v2'!$L$2:$L$361,"FP",'Classificação v2'!$B$2:$B$361,"6.11.1") -> 0 | F9: =COUNTIFS('Classificação v2'!$K$2:$K$361,"FN",'Classificação v2'!$B$2:$B$361,"6.11.1") -> 0 | G9: =COUNTIFS('Classificação v2'!$N$2:$N$361,"FP",'Classificação v2'!$B$2:$B$361,"6.11.1") -> 0
A10: 6.11.2 | B10: =COUNTIFS('Classificação v1'!$K$2:$K$361,"FP",'Classificação v1'!$B$2:$B$361,"6.11.2") -> 0 | C10: =COUNTIFS('Classificação v2'!$K$2:$K$361,"FP",'Classificação v2'!$B$2:$B$361,"6.11.2") -> 0 | D10: =COUNTIFS('Classificação v1'!$L$2:$L$361,"FP",'Classificação v1'!$B$2:$B$361,"6.11.2") -> 0 | E10: =COUNTIFS('Classificação v2'!$L$2:$L$361,"FP",'Classificação v2'!$B$2:$B$361,"6.11.2") -> 0 | F10: =COUNTIFS('Classificação v2'!$K$2:$K$361,"FN",'Classificação v2'!$B$2:$B$361,"6.11.2") -> 0 | G10: =COUNTIFS('Classificação v2'!$N$2:$N$361,"FP",'Classificação v2'!$B$2:$B$361,"6.11.2") -> 0
A11: 6.11.3 | B11: =COUNTIFS('Classificação v1'!$K$2:$K$361,"FP",'Classificação v1'!$B$2:$B$361,"6.11.3") -> 0 | C11: =COUNTIFS('Classificação v2'!$K$2:$K$361,"FP",'Classificação v2'!$B$2:$B$361,"6.11.3") -> 1 | D11: =COUNTIFS('Classificação v1'!$L$2:$L$361,"FP",'Classificação v1'!$B$2:$B$361,"6.11.3") -> 0 | E11: =COUNTIFS('Classificação v2'!$L$2:$L$361,"FP",'Classificação v2'!$B$2:$B$361,"6.11.3") -> 1 | F11: =COUNTIFS('Classificação v2'!$K$2:$K$361,"FN",'Classificação v2'!$B$2:$B$361,"6.11.3") -> 0 | G11: =COUNTIFS('Classificação v2'!$N$2:$N$361,"FP",'Classificação v2'!$B$2:$B$361,"6.11.3") -> 0 | H11: Caso isolado (variação de uma rodada).
A12: 7.5 | B12: =COUNTIFS('Classificação v1'!$K$2:$K$361,"FP",'Classificação v1'!$B$2:$B$361,"7.5") -> 0 | C12: =COUNTIFS('Classificação v2'!$K$2:$K$361,"FP",'Classificação v2'!$B$2:$B$361,"7.5") -> 0 | D12: =COUNTIFS('Classificação v1'!$L$2:$L$361,"FP",'Classificação v1'!$B$2:$B$361,"7.5") -> 0 | E12: =COUNTIFS('Classificação v2'!$L$2:$L$361,"FP",'Classificação v2'!$B$2:$B$361,"7.5") -> 0 | F12: =COUNTIFS('Classificação v2'!$K$2:$K$361,"FN",'Classificação v2'!$B$2:$B$361,"7.5") -> 0 | G12: =COUNTIFS('Classificação v2'!$N$2:$N$361,"FP",'Classificação v2'!$B$2:$B$361,"7.5") -> 0
A13: 7.6-7.8 | B13: =COUNTIFS('Classificação v1'!$K$2:$K$361,"FP",'Classificação v1'!$B$2:$B$361,"7.6-7.8") -> 22 | C13: =COUNTIFS('Classificação v2'!$K$2:$K$361,"FP",'Classificação v2'!$B$2:$B$361,"7.6-7.8") -> 19 | D13: =COUNTIFS('Classificação v1'!$L$2:$L$361,"FP",'Classificação v1'!$B$2:$B$361,"7.6-7.8") -> 22 | E13: =COUNTIFS('Classificação v2'!$L$2:$L$361,"FP",'Classificação v2'!$B$2:$B$361,"7.6-7.8") -> 19 | F13: =COUNTIFS('Classificação v2'!$K$2:$K$361,"FN",'Classificação v2'!$B$2:$B$361,"7.6-7.8") -> 0 | G13: =COUNTIFS('Classificação v2'!$N$2:$N$361,"FP",'Classificação v2'!$B$2:$B$361,"7.6-7.8") -> 0 | H13: Regras de barra por tipo (A, A1, lavatório) exigem cotas 3D; o LLM tende a Parcial.
A14: 7.7.1 | B14: =COUNTIFS('Classificação v1'!$K$2:$K$361,"FP",'Classificação v1'!$B$2:$B$361,"7.7.1") -> 0 | C14: =COUNTIFS('Classificação v2'!$K$2:$K$361,"FP",'Classificação v2'!$B$2:$B$361,"7.7.1") -> 1 | D14: =COUNTIFS('Classificação v1'!$L$2:$L$361,"FP",'Classificação v1'!$B$2:$B$361,"7.7.1") -> 0 | E14: =COUNTIFS('Classificação v2'!$L$2:$L$361,"FP",'Classificação v2'!$B$2:$B$361,"7.7.1") -> 1 | F14: =COUNTIFS('Classificação v2'!$K$2:$K$361,"FN",'Classificação v2'!$B$2:$B$361,"7.7.1") -> 0 | G14: =COUNTIFS('Classificação v2'!$N$2:$N$361,"FP",'Classificação v2'!$B$2:$B$361,"7.7.1") -> 1 | H14: W01: o LLM associou o ambiente reduzido à área de transferência (ambíguo).
A15: 7.7.2.1 | B15: =COUNTIFS('Classificação v1'!$K$2:$K$361,"FP",'Classificação v1'!$B$2:$B$361,"7.7.2.1") -> 28 | C15: =COUNTIFS('Classificação v2'!$K$2:$K$361,"FP",'Classificação v2'!$B$2:$B$361,"7.7.2.1") -> 28 | D15: =COUNTIFS('Classificação v1'!$L$2:$L$361,"FP",'Classificação v1'!$B$2:$B$361,"7.7.2.1") -> 28 | E15: =COUNTIFS('Classificação v2'!$L$2:$L$361,"FP",'Classificação v2'!$B$2:$B$361,"7.7.2.1") -> 28 | F15: =COUNTIFS('Classificação v2'!$K$2:$K$361,"FN",'Classificação v2'!$B$2:$B$361,"7.7.2.1") -> 1 | G15: =COUNTIFS('Classificação v2'!$N$2:$N$361,"FP",'Classificação v2'!$B$2:$B$361,"7.7.2.1") -> 0 | H15: Sem altura explícita da bacia no texto, o LLM marca Indeterminado/Parcial; o Python lê a geometria.
A16: 7.8 | B16: =COUNTIFS('Classificação v1'!$K$2:$K$361,"FP",'Classificação v1'!$B$2:$B$361,"7.8") -> 0 | C16: =COUNTIFS('Classificação v2'!$K$2:$K$361,"FP",'Classificação v2'!$B$2:$B$361,"7.8") -> 0 | D16: =COUNTIFS('Classificação v1'!$L$2:$L$361,"FP",'Classificação v1'!$B$2:$B$361,"7.8") -> 0 | E16: =COUNTIFS('Classificação v2'!$L$2:$L$361,"FP",'Classificação v2'!$B$2:$B$361,"7.8") -> 0 | F16: =COUNTIFS('Classificação v2'!$K$2:$K$361,"FN",'Classificação v2'!$B$2:$B$361,"7.8") -> 0 | G16: =COUNTIFS('Classificação v2'!$N$2:$N$361,"FP",'Classificação v2'!$B$2:$B$361,"7.8") -> 0
A17: Total | B17: =SUM(B5:B16) -> 64 | C17: =SUM(C5:C16) -> 64 | D17: =SUM(D5:D16) -> 109 | E17: =SUM(E5:E16) -> 107 | F17: =SUM(F5:F16) -> 3 | G17: =SUM(G5:G16) -> 1
A19: Leitura: no critério amplo, 'Indeterminado' conta como alarme. A maioria dos FP do LLM é Indeterminado — ele pede revisão humana quando o dado não está explícito no texto.

Sheet Consistência LLM v1×v2
A1: Repetibilidade do LLM: mesmo IFC, mesmo prompt, temperatura 0, duas rodadas
A3: Pares comparados | B3: =COUNTA(A19:A378) -> 360 | D3: Item NBR | E3: Divergências LLM
A4: LLM igual nas 2 rodadas | B4: =SUM(E19:E378) -> 331 | D4: 4.6.6 | E4: =COUNTIFS(B19:B378,"4.6.6",E19:E378,0) -> 1
A5: Consistência LLM | B5: =B4/B3 -> 0.91944444 | D5: 5.4.3 | E5: =COUNTIFS(B19:B378,"5.4.3",E19:E378,0) -> 0
A6: Python igual nas 2 rodadas | B6: =SUM(H19:H378) -> 359 | D6: 6.3.4 | E6: =COUNTIFS(B19:B378,"6.3.4",E19:E378,0) -> 12
A7: Consistência Python | B7: =B6/B3 -> 0.99722222 | D7: 6.6 | E7: =COUNTIFS(B19:B378,"6.6",E19:E378,0) -> 9
D8: 6.11.1 | E8: =COUNTIFS(B19:B378,"6.11.1",E19:E378,0) -> 0
D9: 6.11.2 | E9: =COUNTIFS(B19:B378,"6.11.2",E19:E378,0) -> 1
D10: 6.11.3 | E10: =COUNTIFS(B19:B378,"6.11.3",E19:E378,0) -> 1
D11: 7.5 | E11: =COUNTIFS(B19:B378,"7.5",E19:E378,0) -> 0
D12: 7.6-7.8 | E12: =COUNTIFS(B19:B378,"7.6-7.8",E19:E378,0) -> 3
D13: 7.7.1 | E13: =COUNTIFS(B19:B378,"7.7.1",E19:E378,0) -> 1
D14: 7.7.2.1 | E14: =COUNTIFS(B19:B378,"7.7.2.1",E19:E378,0) -> 1
D15: 7.8 | E15: =COUNTIFS(B19:B378,"7.8",E19:E378,0) -> 0
A17: O Python só mudou em S02/7.7.2.1 (correção do código entre as rodadas, não variação aleatória).
A18: Variante | B18: Item NBR | C18: LLM v1 | D18: LLM v2 | E18: LLM igual | F18: Python v1 | G18: Python v2 | H18: Python igual
A19: B00 | B19: 6.6 | C19: Não Conforme | D19: Conforme | E19: =IF(C19=D19,1,0) -> 0 | F19: Conforme | G19: Conforme | H19: =IF(F19=G19,1,0) -> 1
A20: B00 | B20: 6.11.1 | C20: Conforme | D20: Conforme | E20: =IF(C20=D20,1,0) -> 1 | F20: Conforme | G20: Conforme | H20: =IF(F20=G20,1,0) -> 1
A21: B00 | B21: 6.11.2 | C21: Conforme | D21: Conforme | E21: =IF(C21=D21,1,0) -> 1 | F21: Conforme | G21: Conforme | H21: =IF(F21=G21,1,0) -> 1
A22: B00 | B22: 6.11.3 | C22: Conforme | D22: Conforme | E22: =IF(C22=D22,1,0) -> 1 | F22: Conforme | G22: Conforme | H22: =IF(F22=G22,1,0) -> 1
A23: B00 | B23: 5.4.3 | C23: Conforme | D23: Conforme | E23: =IF(C23=D23,1,0) -> 1 | F23: Conforme | G23: Conforme | H23: =IF(F23=G23,1,0) -> 1
A24: B00 | B24: 6.3.4 | C24: Conforme | D24: Conforme | E24: =IF(C24=D24,1,0) -> 1 | F24: Conforme | G24: Conforme | H24: =IF(F24=G24,1,0) -> 1
A25: B00 | B25: 7.5 | C25: Conforme | D25: Conforme | E25: =IF(C25=D25,1,0) -> 1 | F25: Conforme | G25: Conforme | H25: =IF(F25=G25,1,0) -> 1
A26: B00 | B26: 7.7.2.1 | C26: Não Conforme | D26: Não Conforme | E26: =IF(C26=D26,1,0) -> 1 | F26: Conforme | G26: Conforme | H26: =IF(F26=G26,1,0) -> 1
A27: B00 | B27: 7.7.1 | C27: Conforme | D27: Conforme | E27: =IF(C27=D27,1,0) -> 1 | F27: — | G27: — | H27: =IF(F27=G27,1,0) -> 1
A28: B00 | B28: 4.6.6 | C28: Indeterminado | D28: Indeterminado | E28: =IF(C28=D28,1,0) -> 1 | F28: Conforme | G28: Conforme | H28: =IF(F28=G28,1,0) -> 1
A29: B00 | B29: 7.6-7.8 | C29: Parcial | D29: Parcial | E29: =IF(C29=D29,1,0) -> 1 | F29: Conforme | G29: Conforme | H29: =IF(F29=G29,1,0) -> 1
A30: B00 | B30: 7.8 | C30: Conforme | D30: Conforme | E30: =IF(C30=D30,1,0) -> 1 | F30: Conforme | G30: Conforme | H30: =IF(F30=G30,1,0) -> 1
... A378: X02 | B378: 7.8 | C378: Conforme | D378: Conforme | E378: =IF(C378=D378,1,0) -> 1 | F378: Conforme | G378: Conforme | H378: =IF(F378=G378,1,0) -> 1

Sheet Erros do auditor v2
A1: Divergências da rodada v2 contra o gabarito com errata
A2: Camadas python e final no topo (com causa); camada llm abaixo. Fonte: erros_auditor.csv.
A4: Camada | B4: Variante | C4: Item NBR | D4: Esperado | E4: Obtido | F4: Tipo de erro | G4: Causa | H4: Detalhe do Python
A5: python | B5: S01 | C5: 7.7.2.1 | D5: Não Conforme | E5: Indeterminado | F5: estrito=FN; amplo=categoria | G5: Regra de projeto: bacia fora de 0,41–0,47 m vira 'verificar in loco' (Indeterminado), nunca Não Conforme. FN estrito, acerto no amplo. | H5: Indeterminado: Altura 0.495 m fora da faixa aceitável (< 0.41 m ou > 0.47 m). Requer verificação in loco.
A6: python | B6: S02 | C6: 7.6-7.8 | D6: Parcial | E6: Conforme | F6: estrito=FN; amplo=FN | G6: Barra de fundo a 3,2 cm da tampa (mín. 4 cm) aceita pela tolerância de modelagem de 1 cm (TOL_BARRA_CONF). FN nos dois critérios.
A7: final | B7: S01 | C7: 7.7.2.1 | D7: Não Conforme | E7: Indeterminado | F7: estrito=FN; amplo=categoria | G7: Regra de projeto: bacia fora de 0,41–0,47 m vira 'verificar in loco' (Indeterminado), nunca Não Conforme. FN estrito, acerto no amplo. | H7: Indeterminado: Altura 0.495 m fora da faixa aceitável (< 0.41 m ou > 0.47 m). Requer verificação in loco.
A8: final | B8: S02 | C8: 7.6-7.8 | D8: Parcial | E8: Conforme | F8: estrito=FN; amplo=FN | G8: Barra de fundo a 3,2 cm da tampa (mín. 4 cm) aceita pela tolerância de modelagem de 1 cm (TOL_BARRA_CONF). FN nos dois critérios.
A9: final | B9: W01 | C9: 7.7.1 | D9: Conforme | E9: Não Conforme | F9: estrito=FP; amplo=FP | G9: Python não mede 7.7.1; vale o LLM, que ligou o ambiente reduzido à área de transferência. Ambíguo (ver sensibilidade no Resumo).
A10: llm | B10: A01 | C10: 4.6.6 | D10: Conforme | E10: Indeterminado | F10: estrito=categoria; amplo=FP
A11: llm | B11: A01 | C11: 6.3.4 | D11: Conforme | E11: N/A | F11: estrito=categoria; amplo=categoria
A12: llm | B12: A01 | C12: 7.7.2.1 | D12: Conforme | E12: Não Conforme | F12: estrito=FP; amplo=FP
A13: llm | B13: B00 | C13: 4.6.6 | D13: Conforme | E13: Indeterminado | F13: estrito=categoria; amplo=FP
A14: llm | B14: B00 | C14: 7.6-7.8 | D14: Conforme | E14: Parcial | F14: estrito=FP; amplo=FP
A15: llm | B15: B00 | C15: 7.7.2.1 | D15: Conforme | E15: Não Conforme | F15: estrito=FP; amplo=FP
A16: llm | B16: C01 | C16: 4.6.6 | D16: Conforme | E16: Indeterminado | F16: estrito=categoria; amplo=FP
A17: llm | B17: C01 | C17: 5.4.3 | D17: Parcial | E17: Não Conforme | F17: estrito=categoria; amplo=categoria | H17: Parcial: corrimão em só um lado. Detalhe: lado direito: [2iZFzhqZj33PazahJbF49C] topo 0.92 m, níveis 0,70/0,92 m, acompanha a rampa.
A18: llm | B18: C01 | C18: 6.11.3 | D18: Conforme | E18: Parcial | F18: estrito=FP; amplo=FP
A19: llm | B19: C01 | C19: 7.6-7.8 | D19: Conforme | E19: Parcial | F19: estrito=FP; amplo=FP
A20: llm | B20: C01 | C20: 7.7.2.1 | D20: Conforme | E20: Não Conforme | F20: estrito=FP; amplo=FP
A21: llm | B21: C02 | C21: 4.6.6 | D21: Conforme | E21: Indeterminado | F21: estrito=categoria; amplo=FP
A22: llm | B22: C02 | C22: 6.3.4 | D22: Conforme | E22: Indeterminado | F22: estrito=categoria; amplo=FP
A23: llm | B23: C02 | C23: 6.6 | D23: Conforme | E23: Não Conforme | F23: estrito=FP; amplo=FP
A24: llm | B24: C02 | C24: 7.6-7.8 | D24: Conforme | E24: Parcial | F24: estrito=FP; amplo=FP
A25: llm | B25: C02 | C25: 7.7.2.1 | D25: Conforme | E25: Não Conforme | F25: estrito=FP; amplo=FP
A26: llm | B26: C03 | C26: 4.6.6 | D26: Conforme | E26: Indeterminado | F26: estrito=categoria; amplo=FP
A27: llm | B27: C03 | C27: 6.3.4 | D27: Conforme | E27: Não Conforme | F27: estrito=FP; amplo=FP
A28: llm | B28: C03 | C28: 6.6 | D28: Conforme | E28: Não Conforme | F28: estrito=FP; amplo=FP
A29: llm | B29: C03 | C29: 7.7.2.1 | D29: Conforme | E29: Não Conforme | F29: estrito=FP; amplo=FP
A30: llm | B30: D01 | C30: 4.6.6 | D30: Conforme | E30: Indeterminado | F30: estrito=categoria; amplo=FP
A31: llm | B31: D01 | C31: 6.3.4 | D31: Parcial | E31: Não Conforme | F31: estrito=fora (só amplo); amplo=categoria | H31: Indeterminado: Desnível de 15.0 mm na porta: exige chanfro com inclinação ≤ 1:2 (50%). Nenhum chanfro modelado — verificar detalhe de soleira/obra.
A32: llm | B32: D01 | C32: 7.6-7.8 | D32: Conforme | E32: Parcial | F32: estrito=FP; amplo=FP
A33: llm | B33: D01 | C33: 7.7.2.1 | D33: Conforme | E33: Não Conforme | F33: estrito=FP; amplo=FP
A34: llm | B34: D02 | C34: 4.6.6 | D34: Conforme | E34: Indeterminado | F34: estrito=categoria; amplo=FP
A35: llm | B35: D02 | C35: 6.3.4 | D35: Parcial | E35: Não Conforme | F35: estrito=categoria; amplo=categoria | H35: Não Conforme: Desnível de 30.0 mm na porta: acima de 20 mm é degrau — rota acessível exige rampa.
A36: llm | B36: D02 | C36: 7.6-7.8 | D36: Conforme | E36: Parcial | F36: estrito=FP; amplo=FP
A37: llm | B37: D02 | C37: 7.7.2.1 | D37: Conforme | E37: Não Conforme | F37: estrito=FP; amplo=FP
A38: llm | B38: D03 | C38: 4.6.6 | D38: Conforme | E38: Indeterminado | F38: estrito=categoria; amplo=FP
A39: llm | B39: D03 | C39: 6.6 | D39: Conforme | E39: Não Conforme | F39: estrito=FP; amplo=FP
A40: llm | B40: D03 | C40: 7.6-7.8 | D40: Conforme | E40: Parcial | F40: estrito=FP; amplo=FP
A41: llm | B41: D03 | C41: 7.7.2.1 | D41: Conforme | E41: Não Conforme | F41: estrito=FP; amplo=FP
...

Sheet Classificação v2
A1: Variante | B1: Item NBR | C1: Esperado (gabarito) | D1: Esperado (errata) | E1: Python | F1: LLM | G1: Final | H1: Sensib. W01 (1 = excluir) | I1: Python estrito | J1: Python amplo | K1: LLM estrito | L1: LLM amplo | M1: Final estrito | N1: Final amplo | O1: Python exato | P1: LLM exato | Q1: Final exato
A2: B00 | B2: 6.6 | C2: Conforme | D2: Conforme | E2: Conforme | F2: Conforme | G2: Conforme | H2: 0 | I2: =IF(E2="—","—",IF($C2="Indeterminado","fora",IF(AND($C2<>"Conforme",$C2<>"N/A"),IF(OR(E2="Não Conforme",E2="Parcial"),"VP","FN"),IF(OR(E2="Não Conforme",E2="Parcial"),"FP","VN")))) -> VN | J2: =IF(E2="—","—",IF(AND($C2<>"Conforme",$C2<>"N/A"),IF(OR(E2="Não Conforme",E2="Parcial",E2="Indeterminado"),"VP","FN"),IF(OR(E2="Não Conforme",E2="Parcial",E2="Indeterminado"),"FP","VN"))) -> VN | K2: =IF(F2="—","—",IF($C2="Indeterminado","fora",IF(AND($C2<>"Conforme",$C2<>"N/A"),IF(OR(F2="Não Conforme",F2="Parcial"),"VP","FN"),IF(OR(F2="Não Conforme",F2="Parcial"),"FP","VN")))) -> VN | L2: =IF(F2="—","—",IF(AND($C2<>"Conforme",$C2<>"N/A"),IF(OR(F2="Não Conforme",F2="Parcial",F2="Indeterminado"),"VP","FN"),IF(OR(F2="Não Conforme",F2="Parcial",F2="Indeterminado"),"FP","VN"))) -> VN | M2: =IF(G2="—","—",IF($C2="Indeterminado","fora",IF(AND($C2<>"Conforme",$C2<>"N/A"),IF(OR(G2="Não Conforme",G2="Parcial"),"VP","FN"),IF(OR(G2="Não Conforme",G2="Parcial"),"FP","VN")))) -> VN | N2: =IF(G2="—","—",IF(AND($C2<>"Conforme",$C2<>"N/A"),IF(OR(G2="Não Conforme",G2="Parcial",G2="Indeterminado"),"VP","FN"),IF(OR(G2="Não Conforme",G2="Parcial",G2="Indeterminado"),"FP","VN"))) -> VN | O2: =IF(E2="—","—",IF(E2=$D2,1,0)) -> 1 | P2: =IF(F2="—","—",IF(F2=$D2,1,0)) -> 1 | Q2: =IF(G2="—","—",IF(G2=$D2,1,0)) -> 1
A3: B00 | B3: 6.11.1 | C3: Conforme | D3: Conforme | E3: Conforme | F3: Conforme | G3: Conforme | H3: 0 | I3: =IF(E3="—","—",IF($C3="Indeterminado","fora",IF(AND($C3<>"Conforme",$C3<>"N/A"),IF(OR(E3="Não Conforme",E3="Parcial"),"VP","FN"),IF(OR(E3="Não Conforme",E3="Parcial"),"FP","VN")))) -> VN | J3: =IF(E3="—","—",IF(AND($C3<>"Conforme",$C3<>"N/A"),IF(OR(E3="Não Conforme",E3="Parcial",E3="Indeterminado"),"VP","FN"),IF(OR(E3="Não Conforme",E3="Parcial",E3="Indeterminado"),"FP","VN"))) -> VN | K3: =IF(F3="—","—",IF($C3="Indeterminado","fora",IF(AND($C3<>"Conforme",$C3<>"N/A"),IF(OR(F3="Não Conforme",F3="Parcial"),"VP","FN"),IF(OR(F3="Não Conforme",F3="Parcial"),"FP","VN")))) -> VN | L3: =IF(F3="—","—",IF(AND($C3<>"Conforme",$C3<>"N/A"),IF(OR(F3="Não Conforme",F3="Parcial",F3="Indeterminado"),"VP","FN"),IF(OR(F3="Não Conforme",F3="Parcial",F3="Indeterminado"),"FP","VN"))) -> VN | M3: =IF(G3="—","—",IF($C3="Indeterminado","fora",IF(AND($C3<>"Conforme",$C3<>"N/A"),IF(OR(G3="Não Conforme",G3="Parcial"),"VP","FN"),IF(OR(G3="Não Conforme",G3="Parcial"),"FP","VN")))) -> VN | N3: =IF(G3="—","—",IF(AND($C3<>"Conforme",$C3<>"N/A"),IF(OR(G3="Não Conforme",G3="Parcial",G3="Indeterminado"),"VP","FN"),IF(OR(G3="Não Conforme",G3="Parcial",G3="Indeterminado"),"FP","VN"))) -> VN | O3: =IF(E3="—","—",IF(E3=$D3,1,0)) -> 1 | P3: =IF(F3="—","—",IF(F3=$D3,1,0)) -> 1 | Q3: =IF(G3="—","—",IF(G3=$D3,1,0)) -> 1
A4: B00 | B4: 6.11.2 | C4: Conforme | D4: Conforme | E4: Conforme | F4: Conforme | G4: Conforme | H4: 0 | I4: =IF(E4="—","—",IF($C4="Indeterminado","fora",IF(AND($C4<>"Conforme",$C4<>"N/A"),IF(OR(E4="Não Conforme",E4="Parcial"),"VP","FN"),IF(OR(E4="Não Conforme",E4="Parcial"),"FP","VN")))) -> VN | J4: =IF(E4="—","—",IF(AND($C4<>"Conforme",$C4<>"N/A"),IF(OR(E4="Não Conforme",E4="Parcial",E4="Indeterminado"),"VP","FN"),IF(OR(E4="Não Conforme",E4="Parcial",E4="Indeterminado"),"FP","VN"))) -> VN | K4: =IF(F4="—","—",IF($C4="Indeterminado","fora",IF(AND($C4<>"Conforme",$C4<>"N/A"),IF(OR(F4="Não Conforme",F4="Parcial"),"VP","FN"),IF(OR(F4="Não Conforme",F4="Parcial"),"FP","VN")))) -> VN | L4: =IF(F4="—","—",IF(AND($C4<>"Conforme",$C4<>"N/A"),IF(OR(F4="Não Conforme",F4="Parcial",F4="Indeterminado"),"VP","FN"),IF(OR(F4="Não Conforme",F4="Parcial",F4="Indeterminado"),"FP","VN"))) -> VN | M4: =IF(G4="—","—",IF($C4="Indeterminado","fora",IF(AND($C4<>"Conforme",$C4<>"N/A"),IF(OR(G4="Não Conforme",G4="Parcial"),"VP","FN"),IF(OR(G4="Não Conforme",G4="Parcial"),"FP","VN")))) -> VN | N4: =IF(G4="—","—",IF(AND($C4<>"Conforme",$C4<>"N/A"),IF(OR(G4="Não Conforme",G4="Parcial",G4="Indeterminado"),"VP","FN"),IF(OR(G4="Não Conforme",G4="Parcial",G4="Indeterminado"),"FP","VN"))) -> VN | O4: =IF(E4="—","—",IF(E4=$D4,1,0)) -> 1 | P4: =IF(F4="—","—",IF(F4=$D4,1,0)) -> 1 | Q4: =IF(G4="—","—",IF(G4=$D4,1,0)) -> 1
A5: B00 | B5: 6.11.3 | C5: Conforme | D5: Conforme | E5: Conforme | F5: Conforme | G5: Conforme | H5: 0 | I5: =IF(E5="—","—",IF($C5="Indeterminado","fora",IF(AND($C5<>"Conforme",$C5<>"N/A"),IF(OR(E5="Não Conforme",E5="Parcial"),"VP","FN"),IF(OR(E5="Não Conforme",E5="Parcial"),"FP","VN")))) -> VN | J5: =IF(E5="—","—",IF(AND($C5<>"Conforme",$C5<>"N/A"),IF(OR(E5="Não Conforme",E5="Parcial",E5="Indeterminado"),"VP","FN"),IF(OR(E5="Não Conforme",E5="Parcial",E5="Indeterminado"),"FP","VN"))) -> VN | K5: =IF(F5="—","—",IF($C5="Indeterminado","fora",IF(AND($C5<>"Conforme",$C5<>"N/A"),IF(OR(F5="Não Conforme",F5="Parcial"),"VP","FN"),IF(OR(F5="Não Conforme",F5="Parcial"),"FP","VN")))) -> VN | L5: =IF(F5="—","—",IF(AND($C5<>"Conforme",$C5<>"N/A"),IF(OR(F5="Não Conforme",F5="Parcial",F5="Indeterminado"),"VP","FN"),IF(OR(F5="Não Conforme",F5="Parcial",F5="Indeterminado"),"FP","VN"))) -> VN | M5: =IF(G5="—","—",IF($C5="Indeterminado","fora",IF(AND($C5<>"Conforme",$C5<>"N/A"),IF(OR(G5="Não Conforme",G5="Parcial"),"VP","FN"),IF(OR(G5="Não Conforme",G5="Parcial"),"FP","VN")))) -> VN | N5: =IF(G5="—","—",IF(AND($C5<>"Conforme",$C5<>"N/A"),IF(OR(G5="Não Conforme",G5="Parcial",G5="Indeterminado"),"VP","FN"),IF(OR(G5="Não Conforme",G5="Parcial",G5="Indeterminado"),"FP","VN"))) -> VN | O5: =IF(E5="—","—",IF(E5=$D5,1,0)) -> 1 | P5: =IF(F5="—","—",IF(F5=$D5,1,0)) -> 1 | Q5: =IF(G5="—","—",IF(G5=$D5,1,0)) -> 1
